<sdf version='1.7'>
  <world name='default'>
    <scene>
      <ambient>0.4 0.4 0.4 1</ambient>
      <background>0.7 0.7 0.7 1</background>
      <shadows>1</shadows>
    </scene>
    <light name='sun' type='directional'>
      <cast_shadows>1</cast_shadows>
      <pose>0 0 10 0 -0 0</pose>
      <diffuse>0.8 0.8 0.8 1</diffuse>
      <specular>0.2 0.2 0.2 1</specular>
      <attenuation>
        <range>1000</range>
        <constant>0.9</constant>
        <linear>0.01</linear>
        <quadratic>0.001</quadratic>
      </attenuation>
      <direction>-0.5 0.1 -0.9</direction>
      <spot>
        <inner_angle>0</inner_angle>
        <outer_angle>0</outer_angle>
        <falloff>0</falloff>
      </spot>
    </light>
    <model name='ground_plane'>
      <static>1</static>
      <link name='link'>
        <collision name='collision'>
          <geometry>
            <plane>
              <normal>0 0 1</normal>
              <size>100 100</size>
            </plane>
          </geometry>
          <surface>
            <contact>
              <collide_bitmask>65535</collide_bitmask>
              <ode/>
            </contact>
            <friction>
              <ode>
                <mu>100</mu>
                <mu2>50</mu2>
              </ode>
              <torsional>
                <ode/>
              </torsional>
            </friction>
            <bounce/>
          </surface>
          <max_contacts>10</max_contacts>
        </collision>
        <visual name='visual'>
          <cast_shadows>0</cast_shadows>
          <geometry>
            <plane>
              <normal>0 0 1</normal>
              <size>100 100</size>
            </plane>
          </geometry>
          <material>
            <script>
              <uri>file://media/materials/scripts/gazebo.material</uri>
              <name>Gazebo/Grey</name>
            </script>
          </material>
        </visual>
        <self_collide>0</self_collide>
        <enable_wind>0</enable_wind>
        <kinematic>0</kinematic>
      </link>
    </model>
    <physics type='ode'>
      <max_step_size>0.001</max_step_size>
      <real_time_factor>1</real_time_factor>
      <real_time_update_rate>1000</real_time_update_rate>
    </physics>
    <physics type='ode'>
      <real_time_update_rate>1000</real_time_update_rate>
      <max_step_size>0.001</max_step_size>
      <real_time_factor>1</real_time_factor>
      <ode>
        <solver>
          <type>quick</type>
          <iters>150</iters>
          <precon_iters>0</precon_iters>
          <sor>1.4</sor>
          <use_dynamic_moi_rescaling>1</use_dynamic_moi_rescaling>
        </solver>
        <constraints>
          <cfm>1e-05</cfm>
          <erp>0.2</erp>
          <contact_max_correcting_vel>2000</contact_max_correcting_vel>
          <contact_surface_layer>0.01</contact_surface_layer>
        </constraints>
      </ode>
    </physics>
    <gravity>0 0 -9.81</gravity>
    <magnetic_field>6e-06 2.3e-05 -4.2e-05</magnetic_field>
    <atmosphere type='adiabatic'/>
    <wind/>
    <spherical_coordinates>
      <surface_model>EARTH_WGS84</surface_model>
      <latitude_deg>0</latitude_deg>
      <longitude_deg>0</longitude_deg>
      <elevation>0</elevation>
      <heading_deg>0</heading_deg>
    </spherical_coordinates>
    <model name='robot'>
      <link name='base_link'>
        <inertial>
          <pose>0 0 0 0 -0 0</pose>
          <mass>10</mass>
          <inertia>
            <ixx>0.5</ixx>
            <ixy>0</ixy>
            <ixz>0</ixz>
            <iyy>0.5</iyy>
            <iyz>0</iyz>
            <izz>0.5</izz>
          </inertia>
        </inertial>
        <collision name='base_link_fixed_joint_lump__caster_collision_collision'>
          <pose>-0.15 0 -0.09 0 -0 0</pose>
          <geometry>
            <sphere>
              <radius>0.01</radius>
            </sphere>
          </geometry>
          <max_contacts>10</max_contacts>
          <surface>
            <contact>
              <ode/>
            </contact>
            <bounce/>
            <friction>
              <torsional>
                <ode/>
              </torsional>
              <ode/>
            </friction>
          </surface>
        </collision>
        <collision name='base_link_fixed_joint_lump__caster_collision2_collision_1'>
          <pose>0.15 0 -0.09 0 -0 0</pose>
          <geometry>
            <sphere>
              <radius>0.01</radius>
            </sphere>
          </geometry>
          <max_contacts>10</max_contacts>
          <surface>
            <contact>
              <ode/>
            </contact>
            <bounce/>
            <friction>
              <torsional>
                <ode/>
              </torsional>
              <ode/>
            </friction>
          </surface>
        </collision>
        <collision name='base_link_collision_2'>
          <pose>0 0 0 0 -0 0</pose>
          <geometry>
            <box>
              <size>0.2 0.2 0.1</size>
            </box>
          </geometry>
          <surface>
            <contact>
              <ode/>
            </contact>
            <friction>
              <ode/>
              <torsional>
                <ode/>
              </torsional>
            </friction>
            <bounce/>
          </surface>
          <max_contacts>10</max_contacts>
        </collision>
        <visual name='base_link_fixed_joint_lump__caster_visual_visual'>
          <pose>-0.15 0 -0.09 0 -0 0</pose>
          <geometry>
            <sphere>
              <radius>0.01</radius>
            </sphere>
          </geometry>
        </visual>
        <visual name='base_link_fixed_joint_lump__caster_visual2_visual_1'>
          <pose>0.15 0 -0.09 0 -0 0</pose>
          <geometry>
            <sphere>
              <radius>0.01</radius>
            </sphere>
          </geometry>
        </visual>
        <visual name='base_link_fixed_joint_lump__base_visual_visual_2'>
          <pose>0 0 0 0 -0 0</pose>
          <geometry>
            <box>
              <size>0.2 0.2 0.1</size>
            </box>
          </geometry>
        </visual>
        <visual name='base_link_fixed_joint_lump__camera_visual_visual_3'>
          <pose>0.13 0 0.03 0 -0 0</pose>
          <geometry>
            <box>
              <size>0.05 0.05 0.05</size>
            </box>
          </geometry>
        </visual>
        <visual name='base_link_fixed_joint_lump__lidar_visual_visual_4'>
          <pose>0 0 0.14 0 -0 1.57</pose>
          <geometry>
            <cylinder>
              <length>0.05</length>
              <radius>0.03</radius>
            </cylinder>
          </geometry>
        </visual>
        <sensor name='camera1' type='camera'>
          <update_rate>30</update_rate>
          <camera name='head'>
            <horizontal_fov>1.5</horizontal_fov>
            <image>
              <width>960</width>
              <height>840</height>
              <format>R8G8B8</format>
            </image>
            <clip>
              <near>0.02</near>
              <far>300</far>
            </clip>
          </camera>
          <plugin name='camera_controller' filename='libgazebo_ros_camera.so'>
            <alwaysOn>1</alwaysOn>
            <updateRate>30.0</updateRate>
            <cameraName>diff_drive_robot/camera1</cameraName>
            <imageTopicName>image_raw</imageTopicName>
            <cameraInfoTopicName>camera_info</cameraInfoTopicName>
            <frameName>camera</frameName>
            <hackBaseline>0.07</hackBaseline>
            <distortionK1>0.0</distortionK1>
            <distortionK2>0.0</distortionK2>
            <distortionK3>0.0</distortionK3>
            <distortionT1>0.0</distortionT1>
            <distortionT2>0.0</distortionT2>
            <robotNamespace>/</robotNamespace>
          </plugin>
          <pose>0.13 0 0.03 0 -0 0</pose>
        </sensor>
        <sensor name='lidar_sensor' type='ray'>
          <visualize>0</visualize>
          <update_rate>30</update_rate>
          <ray>
            <scan>
              <horizontal>
                <samples>5</samples>
                <resolution>1</resolution>
                <min_angle>-3.1416</min_angle>
                <max_angle>3.1416</max_angle>
              </horizontal>
              <vertical>
                <samples>1</samples>
                <min_angle>0</min_angle>
                <max_angle>0</max_angle>
              </vertical>
            </scan>
            <range>
              <min>0.4</min>
              <max>10</max>
              <resolution>0.01</resolution>
            </range>
            <noise>
              <type>gaussian</type>
              <mean>0</mean>
              <stddev>0.01</stddev>
            </noise>
          </ray>
          <plugin name='gazebo_ros_head_lidar_controller' filename='libgazebo_ros_laser.so'>
            <topicName>scan</topicName>
            <frameName>lidar_link</frameName>
            <robotNamespace>/</robotNamespace>
          </plugin>
          <pose>0 0 0.14 0 -0 1.57</pose>
        </sensor>
        <self_collide>0</self_collide>
        <enable_wind>0</enable_wind>
        <kinematic>0</kinematic>
      </link>
      <joint name='left_wheel_joint' type='revolute'>
        <pose relative_to='base_link'>0 0.15 0 1.57 -0 0</pose>
        <parent>base_link</parent>
        <child>wheel_left</child>
        <axis>
          <xyz>0 0 -1</xyz>
          <limit>
            <effort>10</effort>
            <velocity>10</velocity>
            <lower>-1e+16</lower>
            <upper>1e+16</upper>
          </limit>
          <dynamics>
            <spring_reference>0</spring_reference>
            <spring_stiffness>0</spring_stiffness>
          </dynamics>
        </axis>
      </joint>
      <link name='wheel_left'>
        <pose relative_to='left_wheel_joint'>0 0 0 0 -0 0</pose>
        <inertial>
          <pose>0 0 0 0 -0 0</pose>
          <mass>1</mass>
          <inertia>
            <ixx>0.1</ixx>
            <ixy>0</ixy>
            <ixz>0</ixz>
            <iyy>0.1</iyy>
            <iyz>0</iyz>
            <izz>0.1</izz>
          </inertia>
        </inertial>
        <collision name='wheel_left_collision'>
          <pose>0 0 0 0 -0 0</pose>
          <geometry>
            <cylinder>
              <length>0.05</length>
              <radius>0.1</radius>
            </cylinder>
          </geometry>
          <max_contacts>10</max_contacts>
          <surface>
            <contact>
              <ode/>
            </contact>
            <bounce/>
            <friction>
              <torsional>
                <ode/>
              </torsional>
              <ode/>
            </friction>
          </surface>
        </collision>
        <visual name='wheel_left_visual_visual'>
          <pose>0 0 0 0 -0 0</pose>
          <geometry>
            <cylinder>
              <length>0.05</length>
              <radius>0.1</radius>
            </cylinder>
          </geometry>
        </visual>
        <self_collide>0</self_collide>
        <enable_wind>0</enable_wind>
        <kinematic>0</kinematic>
      </link>
      <joint name='right_wheel_joint' type='revolute'>
        <pose relative_to='base_link'>0 -0.15 0 1.57 -0 0</pose>
        <parent>base_link</parent>
        <child>wheel_right</child>
        <axis>
          <xyz>0 0 -1</xyz>
          <limit>
            <effort>10</effort>
            <velocity>10</velocity>
            <lower>-1e+16</lower>
            <upper>1e+16</upper>
          </limit>
          <dynamics>
            <spring_reference>0</spring_reference>
            <spring_stiffness>0</spring_stiffness>
          </dynamics>
        </axis>
      </joint>
      <link name='wheel_right'>
        <pose relative_to='right_wheel_joint'>0 0 0 0 -0 0</pose>
        <inertial>
          <pose>0 0 0 0 -0 0</pose>
          <mass>1</mass>
          <inertia>
            <ixx>0.1</ixx>
            <ixy>0</ixy>
            <ixz>0</ixz>
            <iyy>0.1</iyy>
            <iyz>0</iyz>
            <izz>0.1</izz>
          </inertia>
        </inertial>
        <collision name='wheel_right_collision'>
          <pose>0 0 0 0 -0 0</pose>
          <geometry>
            <cylinder>
              <length>0.05</length>
              <radius>0.1</radius>
            </cylinder>
          </geometry>
          <max_contacts>10</max_contacts>
          <surface>
            <contact>
              <ode/>
            </contact>
            <bounce/>
            <friction>
              <torsional>
                <ode/>
              </torsional>
              <ode/>
            </friction>
          </surface>
        </collision>
        <visual name='wheel_right_fixed_joint_lump__wheel_left_visual_visual'>
          <pose>0 0 0 0 -0 0</pose>
          <geometry>
            <cylinder>
              <length>0.05</length>
              <radius>0.1</radius>
            </cylinder>
          </geometry>
        </visual>
        <self_collide>0</self_collide>
        <enable_wind>0</enable_wind>
        <kinematic>0</kinematic>
      </link>
      <static>0</static>
      <plugin name='differential_drive_controller' filename='libgazebo_ros_diff_drive.so'>
        <legacyMode>0</legacyMode>
        <alwaysOn>1</alwaysOn>
        <updateRate>30</updateRate>
        <leftJoint>left_wheel_joint</leftJoint>
        <rightJoint>right_wheel_joint</rightJoint>
        <wheelSeparation>0.3</wheelSeparation>
        <wheelDiameter>0.21</wheelDiameter>
        <wheelTorque>20</wheelTorque>
        <commandTopic>cmd_vel</commandTopic>
        <odometryTopic>/diff_drive_robot/odom</odometryTopic>
        <odometryFrame>odom</odometryFrame>
        <robotBaseFrame>base_link</robotBaseFrame>
        <robotNamespace>/</robotNamespace>
      </plugin>
      <pose>0 0 0 0 -0 0</pose>
    </model>
    <model name='unit_cylinder'>
      <pose>2.1767 0.137172 0.5 0 -0 0</pose>
      <link name='link'>
        <inertial>
          <mass>1</mass>
          <inertia>
            <ixx>0.145833</ixx>
            <ixy>0</ixy>
            <ixz>0</ixz>
            <iyy>0.145833</iyy>
            <iyz>0</iyz>
            <izz>0.125</izz>
          </inertia>
          <pose>0 0 0 0 -0 0</pose>
        </inertial>
        <collision name='collision'>
          <geometry>
            <cylinder>
              <radius>0.5</radius>
              <length>1</length>
            </cylinder>
          </geometry>
          <max_contacts>10</max_contacts>
          <surface>
            <contact>
              <ode/>
            </contact>
            <bounce/>
            <friction>
              <torsional>
                <ode/>
              </torsional>
              <ode/>
            </friction>
          </surface>
        </collision>
        <visual name='visual'>
          <geometry>
            <cylinder>
              <radius>0.5</radius>
              <length>1</length>
            </cylinder>
          </geometry>
          <material>
            <script>
              <name>Gazebo/Grey</name>
              <uri>file://media/materials/scripts/gazebo.material</uri>
            </script>
          </material>
        </visual>
        <self_collide>0</self_collide>
        <enable_wind>0</enable_wind>
        <kinematic>0</kinematic>
      </link>
    </model>
    <state world_name='default'>
      <sim_time>70 576000000</sim_time>
      <real_time>79 371780041</real_time>
      <wall_time>1743963157 32980898</wall_time>
      <iterations>70576</iterations>
      <model name='ground_plane'>
        <pose>0 0 0 0 -0 0</pose>
        <scale>1 1 1</scale>
        <link name='link'>
          <pose>0 0 0 0 -0 0</pose>
          <velocity>0 0 0 0 -0 0</velocity>
          <acceleration>0 0 0 0 -0 0</acceleration>
          <wrench>0 0 0 0 -0 0</wrench>
        </link>
      </model>
      <model name='robot'>
        <pose>-1e-06 1.8e-05 0.100017 5e-06 -4.2e-05 1.8e-05</pose>
        <scale>1 1 1</scale>
        <link name='base_link'>
          <pose>-1e-06 1.8e-05 0.100017 5e-06 -4.2e-05 1.8e-05</pose>
          <velocity>1e-06 0.000689 0.001664 -0.007721 1e-05 0</velocity>
          <acceleration>-2.5e-05 1.37815 3.32854 -2.87505 -0.000279 -0</acceleration>
          <wrench>-0.000249 13.7815 33.2854 0 -0 0</wrench>
        </link>
        <link name='wheel_left'>
          <pose>-4e-06 0.150018 0.10002 1.57001 -4.3e-05 1.8e-05</pose>
          <velocity>1e-06 0.000773 0.000191 -0.007719 1e-05 -0</velocity>
          <acceleration>-2.8e-05 1.54454 0.382516 -2.87204 -0.000279 0</acceleration>
          <wrench>-2.8e-05 1.54454 0.382516 0 -0 0</wrench>
        </link>
        <link name='wheel_right'>
          <pose>2e-06 -0.149981 0.10002 1.57001 -3.8e-05 1.8e-05</pose>
          <velocity>1e-06 0.000765 0.003507 -0.007652 1e-05 0</velocity>
          <acceleration>-2.8e-05 1.5291 7.01437 -2.73697 -0.000276 -0</acceleration>
          <wrench>-2.8e-05 1.5291 7.01437 0 -0 0</wrench>
        </link>
      </model>
      <model name='unit_cylinder'>
        <pose>2.1767 0.137174 0.499997 -4e-06 -4e-06 -0</pose>
        <scale>1 1 1</scale>
        <link name='link'>
          <pose>2.1767 0.137174 0.499997 -4e-06 -4e-06 -0</pose>
          <velocity>0 0 0 0 -0 0</velocity>
          <acceleration>0 0 -9.81 0 -0 0</acceleration>
          <wrench>0 0 -9.81 0 -0 0</wrench>
        </link>
      </model>
      <light name='sun'>
        <pose>0 0 10 0 -0 0</pose>
      </light>
    </state>
    <gui fullscreen='0'>
      <camera name='user_camera'>
        <pose>2.15671 -3.379 3.44725 0 0.666075 2.02943</pose>
        <view_controller>orbit</view_controller>
        <projection_type>perspective</projection_type>
      </camera>
    </gui>
  </world>
</sdf>
